Workbook

Sheet README
A1: Exhibit 21 Parent–Subsidiary Report
A3: Companies covered: AAPL (Apple Inc.), MSFT (Microsoft Corporation)
A4: Source: Exhibit 21 ("Subsidiaries of the Registrant") attached to each company's Form 10-K on SEC EDGAR. Every row keeps its accession number and source link.
A6: Sheets
A7: Summary — subsidiaries listed and countries covered, per company per fiscal year, plus additions / removals / renames vs the prior year.
A8: Parent → Subsidiaries — the latest list for each company. Start here.
A9: Timeline — one row per subsidiary; ✓ shows which years it was listed; status = listed every year / new / no longer listed / name changed.
A10: Changes — year-over-year events: Added, Removed, Renamed, Jurisdiction changed.
A11: All Records — every parsed row (one row = one subsidiary in one 10-K) with full provenance.
A12: QA — parsing checks per filing: rows parsed, duplicates, missing jurisdictions, files that need review.
A14: How to read it
A15: 1. Exhibit 21 lists significant subsidiaries only (Reg. S-K Item 601(b)(21)); companies may omit subsidiaries that together are not significant. It is not a complete list.
... A18: 4. Cross-year matching: identical names are the same entity; names that match once legal suffixes (Inc., Limited, Unlimited Company, ...) are removed, and are unambiguous that year, are treated as a rename.

Sheet Summary
A1: Ticker | B1: Parent company | C1: Fiscal year | D1: Subsidiaries listed | E1: Countries | F1: Added vs prior year | G1: Removed vs prior year | H1: Renamed
A2: AAPL | B2: Apple Inc. | C2: 2023 | D2: =COUNTIFS('All Records'!$A$2:$A$81,A2,'All Records'!$D$2:$D$81,C2) -> 18 | E2: 12 | F2: =COUNTIFS(Changes!$A$2:$A$7,A2,Changes!$B$2:$B$7,C2,Changes!$C$2:$C$7,"Added") -> 0 | G2: =COUNTIFS(Changes!$A$2:$A$7,A2,Changes!$B$2:$B$7,C2,Changes!$C$2:$C$7,"Removed") -> 0 | H2: =COUNTIFS(Changes!$A$2:$A$7,A2,Changes!$B$2:$B$7,C2,Changes!$C$2:$C$7,"Renamed") -> 0
A3: AAPL | B3: Apple Inc. | C3: 2024 | D3: =COUNTIFS('All Records'!$A$2:$A$81,A3,'All Records'!$D$2:$D$81,C3) -> 18 | E3: 12 | F3: =COUNTIFS(Changes!$A$2:$A$7,A3,Changes!$B$2:$B$7,C3,Changes!$C$2:$C$7,"Added") -> 0 | G3: =COUNTIFS(Changes!$A$2:$A$7,A3,Changes!$B$2:$B$7,C3,Changes!$C$2:$C$7,"Removed") -> 0 | H3: =COUNTIFS(Changes!$A$2:$A$7,A3,Changes!$B$2:$B$7,C3,Changes!$C$2:$C$7,"Renamed") -> 0
A4: AAPL | B4: Apple Inc. | C4: 2025 | D4: =COUNTIFS('All Records'!$A$2:$A$81,A4,'All Records'!$D$2:$D$81,C4) -> 19 | E4: 13 | F4: =COUNTIFS(Changes!$A$2:$A$7,A4,Changes!$B$2:$B$7,C4,Changes!$C$2:$C$7,"Added") -> 2 | G4: =COUNTIFS(Changes!$A$2:$A$7,A4,Changes!$B$2:$B$7,C4,Changes!$C$2:$C$7,"Removed") -> 1 | H4: =COUNTIFS(Changes!$A$2:$A$7,A4,Changes!$B$2:$B$7,C4,Changes!$C$2:$C$7,"Renamed") -> 0
A5: MSFT | B5: Microsoft Corporation | C5: 2024 | D5: =COUNTIFS('All Records'!$A$2:$A$81,A5,'All Records'!$D$2:$D$81,C5) -> 9 | E5: 2 | F5: =COUNTIFS(Changes!$A$2:$A$7,A5,Changes!$B$2:$B$7,C5,Changes!$C$2:$C$7,"Added") -> 0 | G5: =COUNTIFS(Changes!$A$2:$A$7,A5,Changes!$B$2:$B$7,C5,Changes!$C$2:$C$7,"Removed") -> 0 | H5: =COUNTIFS(Changes!$A$2:$A$7,A5,Changes!$B$2:$B$7,C5,Changes!$C$2:$C$7,"Renamed") -> 0
A6: MSFT | B6: Microsoft Corporation | C6: 2025 | D6: =COUNTIFS('All Records'!$A$2:$A$81,A6,'All Records'!$D$2:$D$81,C6) -> 8 | E6: 2 | F6: =COUNTIFS(Changes!$A$2:$A$7,A6,Changes!$B$2:$B$7,C6,Changes!$C$2:$C$7,"Added") -> 0 | G6: =COUNTIFS(Changes!$A$2:$A$7,A6,Changes!$B$2:$B$7,C6,Changes!$C$2:$C$7,"Removed") -> 1 | H6: =COUNTIFS(Changes!$A$2:$A$7,A6,Changes!$B$2:$B$7,C6,Changes!$C$2:$C$7,"Renamed") -> 2
A7: MSFT | B7: Microsoft Corporation | C7: 2026 | D7: =COUNTIFS('All Records'!$A$2:$A$81,A7,'All Records'!$D$2:$D$81,C7) -> 8 | E7: 2 | F7: =COUNTIFS(Changes!$A$2:$A$7,A7,Changes!$B$2:$B$7,C7,Changes!$C$2:$C$7,"Added") -> 0 | G7: =COUNTIFS(Changes!$A$2:$A$7,A7,Changes!$B$2:$B$7,C7,Changes!$C$2:$C$7,"Removed") -> 0 | H7: =COUNTIFS(Changes!$A$2:$A$7,A7,Changes!$B$2:$B$7,C7,Changes!$C$2:$C$7,"Renamed") -> 0
A9: Countries = distinct countries in that year's list (computed by the pipeline). Other counts are formulas over the All Records and Changes sheets.

Sheet Parent → Subsidiaries
A1: Parent company | B1: Fiscal year | C1: Subsidiary | D1: Immediate parent (per filing) | E1: Country | F1: State / region | G1: Jurisdiction (as filed) | H1: 3-year status | I1: Source (accession)
A2: Apple Inc. (AAPL) | B2: FY2025 | C2: Apple Pty Limited | D2: Apple Inc. | E2: Australia | G2: Australia | H2: Listed every year | I2: 0000320193-25-000079
A3: Apple Inc. (AAPL) | B3: FY2025 | C3: Apple Canada Inc. | D3: Apple Inc. | E3: Canada | G3: Canada | H3: Listed every year | I3: 0000320193-25-000079
A4: Apple Inc. (AAPL) | B4: FY2025 | C4: Apple Computer Trading (Shanghai) Co., Ltd. | D4: Apple Inc. | E4: China | G4: China | H4: Listed every year | I4: 0000320193-25-000079
A5: Apple Inc. (AAPL) | B5: FY2025 | C5: Apple Asia Limited | D5: Apple Inc. | E5: Hong Kong | G5: Hong Kong | H5: Listed every year | I5: 0000320193-25-000079
A6: Apple Inc. (AAPL) | B6: FY2025 | C6: Apple India Private Limited | D6: Apple Inc. | E6: India | G6: India | H6: Listed every year | I6: 0000320193-25-000079
A7: Apple Inc. (AAPL) | B7: FY2025 | C7: Apple Distribution International Limited | D7: Apple Inc. | E7: Ireland | G7: Ireland | H7: Listed every year | I7: 0000320193-25-000079
A8: Apple Inc. (AAPL) | B8: FY2025 | C8: Apple Operations International Limited | D8: Apple Inc. | E8: Ireland | G8: Ireland | H8: Listed every year | I8: 0000320193-25-000079
A9: Apple Inc. (AAPL) | B9: FY2025 | C9: Apple Operations Limited | D9: Apple Inc. | E9: Ireland | G9: Ireland | H9: Listed every year | I9: 0000320193-25-000079
A10: Apple Inc. (AAPL) | B10: FY2025 | C10: Apple Japan, Inc. | D10: Apple Inc. | E10: Japan | G10: Japan | H10: Listed every year | I10: 0000320193-25-000079
A11: Apple Inc. (AAPL) | B11: FY2025 | C11: iTunes K.K. | D11: Apple Inc. | E11: Japan | G11: Japan | H11: Listed every year | I11: 0000320193-25-000079
A12: Apple Inc. (AAPL) | B12: FY2025 | C12: Apple Operations Mexico, S.A. de C.V. | D12: Apple Inc. | E12: Mexico | G12: Mexico | H12: Listed every year | I12: 0000320193-25-000079
A13: Apple Inc. (AAPL) | B13: FY2025 | C13: Apple Services Pte. Ltd. | D13: Apple Inc. | E13: Singapore | G13: Singapore | H13: New in FY2025 | I13: 0000320193-25-000079
... A16: Apple Inc. (AAPL) | B16: FY2025 | C16: Apple South Asia (Thailand) Limited | D16: Apple Inc. | E16: Thailand | G16: Thailand | H16: Listed every year | I16: 0000320193-25-000079
A17: Apple Inc. (AAPL) | B17: FY2025 | C17: Apple Asia LLC | D17: Apple Inc. | E17: United States | F17: Delaware | G17: Delaware, U.S. | H17: Listed every year | I17: 0000320193-25-000079
A18: Apple Inc. (AAPL) | B18: FY2025 | C18: Apple Insurance Company, Inc. | D18: Apple Inc. | E18: United States | F18: Arizona | G18: Arizona, U.S. | H18: Listed every year | I18: 0000320193-25-000079
A19: Apple Inc. (AAPL) | B19: FY2025 | C19: Braeburn Capital, Inc. | D19: Apple Inc. | E19: United States | F19: Nevada | G19: Nevada, U.S. | H19: Listed every year | I19: 0000320193-25-000079
A20: Apple Inc. (AAPL) | B20: FY2025 | C20: Apple Vietnam Limited Liability Company | D20: Apple Inc. | E20: Vietnam | G20: Vietnam | H20: Listed every year | I20: 0000320193-25-000079
A21: Microsoft Corporation (MSFT) | B21: FY2026 | C21: LinkedIn Ireland Unlimited Company | D21: Microsoft Corporation | E21: Ireland | G21: Ireland | H21: Listed every year | I21: 0001193125-26-323660
A22: Microsoft Corporation (MSFT) | B22: FY2026 | C22: Microsoft Global Finance Unlimited Company | D22: Microsoft Corporation | E22: Ireland | G22: Ireland | H22: Listed every year · name changed | I22: 0001193125-26-323660
A23: Microsoft Corporation (MSFT) | B23: FY2026 | C23: Microsoft Ireland Operations Limited | D23: Microsoft Corporation | E23: Ireland | G23: Ireland | H23: Listed every year | I23: 0001193125-26-323660
A24: Microsoft Corporation (MSFT) | B24: FY2026 | C24: Microsoft Ireland Research Unlimited Company | D24: Microsoft Corporation | E24: Ireland | G24: Ireland | H24: Listed every year · name changed | I24: 0001193125-26-323660
A25: Microsoft Corporation (MSFT) | B25: FY2026 | C25: Activision Blizzard, Inc. | D25: Microsoft Corporation | E25: United States | G25: United States | H25: Listed every year | I25: 0001193125-26-323660
A26: Microsoft Corporation (MSFT) | B26: FY2026 | C26: Activision Publishing, Inc. | D26: Microsoft Corporation | E26: United States | G26: United States | H26: Listed every year | I26: 0001193125-26-323660
A27: Microsoft Corporation (MSFT) | B27: FY2026 | C27: LinkedIn Corporation | D27: Microsoft Corporation | E27: United States | G27: United States | H27: Listed every year | I27: 0001193125-26-323660
A28: Microsoft Corporation (MSFT) | B28: FY2026 | C28: Microsoft Online, Inc. | D28: Microsoft Corporation | E28: United States | G28: United States | H28: Listed every year | I28: 0001193125-26-323660

Sheet Timeline
A1: Parent | B1: subsidiary_name (latest) | C1: earlier names | D1: country | E1: jurisdiction (as filed) | F1: FY2023 | G1: FY2024 | H1: FY2025 | I1: FY2026 | J1: status | K1: entity_id
A2: AAPL | B2: Apple Asia LLC | D2: United States | E2: Delaware, U.S. | F2: ✓ | G2: ✓ | H2: ✓ | J2: Listed every year | K2: AAPL-S0002
A3: AAPL | B3: Apple Asia Limited | D3: Hong Kong | E3: Hong Kong | F3: ✓ | G3: ✓ | H3: ✓ | J3: Listed every year | K3: AAPL-S0001
A4: AAPL | B4: Apple Canada Inc. | D4: Canada | E4: Canada | F4: ✓ | G4: ✓ | H4: ✓ | J4: Listed every year | K4: AAPL-S0003
A5: AAPL | B5: Apple Computer Trading (Shanghai) Co., Ltd. | D5: China | E5: China | F5: ✓ | G5: ✓ | H5: ✓ | J5: Listed every year | K5: AAPL-S0004
A6: AAPL | B6: Apple Distribution International Limited | D6: Ireland | E6: Ireland | F6: ✓ | G6: ✓ | H6: ✓ | J6: Listed every year | K6: AAPL-S0005
A7: AAPL | B7: Apple India Private Limited | D7: India | E7: India | F7: ✓ | G7: ✓ | H7: ✓ | J7: Listed every year | K7: AAPL-S0006
A8: AAPL | B8: Apple Insurance Company, Inc. | D8: United States | E8: Arizona, U.S. | F8: ✓ | G8: ✓ | H8: ✓ | J8: Listed every year | K8: AAPL-S0007
A9: AAPL | B9: Apple Japan, Inc. | D9: Japan | E9: Japan | F9: ✓ | G9: ✓ | H9: ✓ | J9: Listed every year | K9: AAPL-S0008
A10: AAPL | B10: Apple Korea Limited | D10: South Korea | E10: South Korea | F10: ✓ | G10: ✓ | H10: ✓ | J10: Listed every year | K10: AAPL-S0009
A11: AAPL | B11: Apple Operations International Limited | D11: Ireland | E11: Ireland | F11: ✓ | G11: ✓ | H11: ✓ | J11: Listed every year | K11: AAPL-S0010
A12: AAPL | B12: Apple Operations Limited | D12: Ireland | E12: Ireland | F12: ✓ | G12: ✓ | H12: ✓ | J12: Listed every year | K12: AAPL-S0011
A13: AAPL | B13: Apple Operations Mexico, S.A. de C.V. | D13: Mexico | E13: Mexico | F13: ✓ | G13: ✓ | H13: ✓ | J13: Listed every year | K13: AAPL-S0012
... A18: AAPL | B18: iTunes K.K. | D18: Japan | E18: Japan | F18: ✓ | G18: ✓ | H18: ✓ | J18: Listed every year | K18: AAPL-S0018
A19: AAPL | B19: Apple Sales International Limited | D19: Ireland | E19: Ireland | F19: ✓ | G19: ✓ | J19: No longer listed after FY2024 | K19: AAPL-S0014
A20: AAPL | B20: Apple Services Pte. Ltd. | D20: Singapore | E20: Singapore | H20: ✓ | J20: New in FY2025 | K20: AAPL-S0019
A21: AAPL | B21: Apple South Asia Pte. Ltd. | D21: Singapore | E21: Singapore | H21: ✓ | J21: New in FY2025 | K21: AAPL-S0020
A22: MSFT | B22: Activision Blizzard, Inc. | D22: United States | E22: United States | G22: ✓ | H22: ✓ | I22: ✓ | J22: Listed every year | K22: MSFT-S0008
A23: MSFT | B23: Activision Publishing, Inc. | D23: United States | E23: United States | G23: ✓ | H23: ✓ | I23: ✓ | J23: Listed every year | K23: MSFT-S0009
A24: MSFT | B24: LinkedIn Corporation | D24: United States | E24: United States | G24: ✓ | H24: ✓ | I24: ✓ | J24: Listed every year | K24: MSFT-S0005
A25: MSFT | B25: LinkedIn Ireland Unlimited Company | D25: Ireland | E25: Ireland | G25: ✓ | H25: ✓ | I25: ✓ | J25: Listed every year | K25: MSFT-S0006
A26: MSFT | B26: Microsoft Ireland Operations Limited | D26: Ireland | E26: Ireland | G26: ✓ | H26: ✓ | I26: ✓ | J26: Listed every year | K26: MSFT-S0003
A27: MSFT | B27: Microsoft Online, Inc. | D27: United States | E27: United States | G27: ✓ | H27: ✓ | I27: ✓ | J27: Listed every year | K27: MSFT-S0004
A28: MSFT | B28: Microsoft Global Finance Unlimited Company | C28: Microsoft Global Finance | D28: Ireland | E28: Ireland | G28: ✓ | H28: ✓ | I28: ✓ | J28: Listed every year · name changed | K28: MSFT-S0002
A29: MSFT | B29: Microsoft Ireland Research Unlimited Company | C29: Microsoft Ireland Research | D29: Ireland | E29: Ireland | G29: ✓ | H29: ✓ | I29: ✓ | J29: Listed every year · name changed | K29: MSFT-S0001
A30: MSFT | B30: Nuance Communications, Inc. | D30: United States | E30: United States | G30: ✓ | J30: No longer listed after FY2024 | K30: MSFT-S0007
A32: Blank FY cell = that parent did not file for that year in this dataset, or the subsidiary was not listed.

Sheet Changes
A1: parent_ticker | B1: fiscal_year | C1: change | D1: subsidiary_name | E1: jurisdiction (as filed) | F1: detail
A2: AAPL | B2: 2025 | C2: Added | D2: Apple Services Pte. Ltd. | E2: Singapore | F2: First appears in this year's Exhibit 21
A3: AAPL | B3: 2025 | C3: Added | D3: Apple South Asia Pte. Ltd. | E3: Singapore | F3: First appears in this year's Exhibit 21
A4: AAPL | B4: 2025 | C4: Removed | D4: Apple Sales International Limited | F4: Not in this year's Exhibit 21
A5: MSFT | B5: 2025 | C5: Removed | D5: Nuance Communications, Inc. | F5: Not in this year's Exhibit 21
A6: MSFT | B6: 2025 | C6: Renamed | D6: Microsoft Global Finance Unlimited Company | E6: Ireland | F6: Previously listed as “Microsoft Global Finance”
A7: MSFT | B7: 2025 | C7: Renamed | D7: Microsoft Ireland Research Unlimited Company | E7: Ireland | F7: Previously listed as “Microsoft Ireland Research”

Sheet All Records
A1: parent_ticker | B1: parent_name | C1: parent_cik | D1: fiscal_year | E1: period_end | F1: accession | G1: subsidiary_name | H1: immediate_parent | I1: relationship | J1: level | K1: jurisdiction_raw | L1: country | M1: state_or_region | N1: ownership_pct | O1: entity_id | P1: row_order | Q1: flags | R1: name_change_note | S1: source_url
A2: AAPL | B2: Apple Inc. | C2: 0000320193 | D2: 2023 | E2: 2023-09-30 | F2: 0000320193-23-000106 | G2: Apple Asia Limited | H2: Apple Inc. | I2: subsidiary of registrant (direct/indirect not stated) | J2: 0 | K2: Hong Kong | L2: Hong Kong | O2: AAPL-S0001 | P2: 1 | S2: https://www.sec.gov/Archives/edgar/data/320193/000032019323000106/a10-kexhibit21109302023.htm
A3: AAPL | B3: Apple Inc. | C3: 0000320193 | D3: 2023 | E3: 2023-09-30 | F3: 0000320193-23-000106 | G3: Apple Asia LLC | H3: Apple Inc. | I3: subsidiary of registrant (direct/indirect not stated) | J3: 0 | K3: Delaware, U.S. | L3: United States | M3: Delaware | O3: AAPL-S0002 | P3: 2 | S3: https://www.sec.gov/Archives/edgar/data/320193/000032019323000106/a10-kexhibit21109302023.htm
A4: AAPL | B4: Apple Inc. | C4: 0000320193 | D4: 2023 | E4: 2023-09-30 | F4: 0000320193-23-000106 | G4: Apple Canada Inc. | H4: Apple Inc. | I4: subsidiary of registrant (direct/indirect not stated) | J4: 0 | K4: Canada | L4: Canada | O4: AAPL-S0003 | P4: 3 | S4: https://www.sec.gov/Archives/edgar/data/320193/000032019323000106/a10-kexhibit21109302023.htm
A5: AAPL | B5: Apple Inc. | C5: 0000320193 | D5: 2023 | E5: 2023-09-30 | F5: 0000320193-23-000106 | G5: Apple Computer Trading (Shanghai) Co., Ltd. | H5: Apple Inc. | I5: subsidiary of registrant (direct/indirect not stated) | J5: 0 | K5: China | L5: China | O5: AAPL-S0004 | P5: 4 | S5: https://www.sec.gov/Archives/edgar/data/320193/000032019323000106/a10-kexhibit21109302023.htm
A6: AAPL | B6: Apple Inc. | C6: 0000320193 | D6: 2023 | E6: 2023-09-30 | F6: 0000320193-23-000106 | G6: Apple Distribution International Limited | H6: Apple Inc. | I6: subsidiary of registrant (direct/indirect not stated) | J6: 0 | K6: Ireland | L6: Ireland | O6: AAPL-S0005 | P6: 5 | S6: https://www.sec.gov/Archives/edgar/data/320193/000032019323000106/a10-kexhibit21109302023.htm
A7: AAPL | B7: Apple Inc. | C7: 0000320193 | D7: 2023 | E7: 2023-09-30 | F7: 0000320193-23-000106 | G7: Apple India Private Limited | H7: Apple Inc. | I7: subsidiary of registrant (direct/indirect not stated) | J7: 0 | K7: India | L7: India | O7: AAPL-S0006 | P7: 6 | S7: https://www.sec.gov/Archives/edgar/data/320193/000032019323000106/a10-kexhibit21109302023.htm
A8: AAPL | B8: Apple Inc. | C8: 0000320193 | D8: 2023 | E8: 2023-09-30 | F8: 0000320193-23-000106 | G8: Apple Insurance Company, Inc. | H8: Apple Inc. | I8: subsidiary of registrant (direct/indirect not stated) | J8: 0 | K8: Arizona, U.S. | L8: United States | M8: Arizona | O8: AAPL-S0007 | P8: 7 | S8: https://www.sec.gov/Archives/edgar/data/320193/000032019323000106/a10-kexhibit21109302023.htm
A9: AAPL | B9: Apple Inc. | C9: 0000320193 | D9: 2023 | E9: 2023-09-30 | F9: 0000320193-23-000106 | G9: Apple Japan, Inc. | H9: Apple Inc. | I9: subsidiary of registrant (direct/indirect not stated) | J9: 0 | K9: Japan | L9: Japan | O9: AAPL-S0008 | P9: 8 | S9: https://www.sec.gov/Archives/edgar/data/320193/000032019323000106/a10-kexhibit21109302023.htm
A10: AAPL | B10: Apple Inc. | C10: 0000320193 | D10: 2023 | E10: 2023-09-30 | F10: 0000320193-23-000106 | G10: Apple Korea Limited | H10: Apple Inc. | I10: subsidiary of registrant (direct/indirect not stated) | J10: 0 | K10: South Korea | L10: South Korea | O10: AAPL-S0009 | P10: 9 | S10: https://www.sec.gov/Archives/edgar/data/320193/000032019323000106/a10-kexhibit21109302023.htm
A11: AAPL | B11: Apple Inc. | C11: 0000320193 | D11: 2023 | E11: 2023-09-30 | F11: 0000320193-23-000106 | G11: Apple Operations International Limited | H11: Apple Inc. | I11: subsidiary of registrant (direct/indirect not stated) | J11: 0 | K11: Ireland | L11: Ireland | O11: AAPL-S0010 | P11: 10 | S11: https://www.sec.gov/Archives/edgar/data/320193/000032019323000106/a10-kexhibit21109302023.htm
A12: AAPL | B12: Apple Inc. | C12: 0000320193 | D12: 2023 | E12: 2023-09-30 | F12: 0000320193-23-000106 | G12: Apple Operations Limited | H12: Apple Inc. | I12: subsidiary of registrant (direct/indirect not stated) | J12: 0 | K12: Ireland | L12: Ireland | O12: AAPL-S0011 | P12: 11 | S12: https://www.sec.gov/Archives/edgar/data/320193/000032019323000106/a10-kexhibit21109302023.htm
A13: AAPL | B13: Apple Inc. | C13: 0000320193 | D13: 2023 | E13: 2023-09-30 | F13: 0000320193-23-000106 | G13: Apple Operations Mexico, S.A. de C.V. | H13: Apple Inc. | I13: subsidiary of registrant (direct/indirect not stated) | J13: 0 | K13: Mexico | L13: Mexico | O13: AAPL-S0012 | P13: 12 | S13: https://www.sec.gov/Archives/edgar/data/320193/000032019323000106/a10-kexhibit21109302023.htm
A14: AAPL | B14: Apple Inc. | C14: 0000320193 | D14: 2023 | E14: 2023-09-30 | F14: 0000320193-23-000106 | G14: Apple Pty Limited | H14: Apple Inc. | I14: subsidiary of registrant (direct/indirect not stated) | J14: 0 | K14: Australia | L14: Australia | O14: AAPL-S0013 | P14: 13 | S14: https://www.sec.gov/Archives/edgar/data/320193/000032019323000106/a10-kexhibit21109302023.htm
A15: AAPL | B15: Apple Inc. | C15: 0000320193 | D15: 2023 | E15: 2023-09-30 | F15: 0000320193-23-000106 | G15: Apple Sales International Limited | H15: Apple Inc. | I15: subsidiary of registrant (direct/indirect not stated) | J15: 0 | K15: Ireland | L15: Ireland | O15: AAPL-S0014 | P15: 14 | S15: https://www.sec.gov/Archives/edgar/data/320193/000032019323000106/a10-kexhibit21109302023.htm
A16: AAPL | B16: Apple Inc. | C16: 0000320193 | D16: 2023 | E16: 2023-09-30 | F16: 0000320193-23-000106 | G16: Apple South Asia (Thailand) Limited | H16: Apple Inc. | I16: subsidiary of registrant (direct/indirect not stated) | J16: 0 | K16: Thailand | L16: Thailand | O16: AAPL-S0015 | P16: 15 | S16: https://www.sec.gov/Archives/edgar/data/320193/000032019323000106/a10-kexhibit21109302023.htm
A17: AAPL | B17: Apple Inc. | C17: 0000320193 | D17: 2023 | E17: 2023-09-30 | F17: 0000320193-23-000106 | G17: Apple Vietnam Limited Liability Company | H17: Apple Inc. | I17: subsidiary of registrant (direct/indirect not stated) | J17: 0 | K17: Vietnam | L17: Vietnam | O17: AAPL-S0016 | P17: 16 | S17: https://www.sec.gov/Archives/edgar/data/320193/000032019323000106/a10-kexhibit21109302023.htm
A18: AAPL | B18: Apple Inc. | C18: 0000320193 | D18: 2023 | E18: 2023-09-30 | F18: 0000320193-23-000106 | G18: Braeburn Capital, Inc. | H18: Apple Inc. | I18: subsidiary of registrant (direct/indirect not stated) | J18: 0 | K18: Nevada, U.S. | L18: United States | M18: Nevada | O18: AAPL-S0017 | P18: 17 | S18: https://www.sec.gov/Archives/edgar/data/320193/000032019323000106/a10-kexhibit21109302023.htm
A19: AAPL | B19: Apple Inc. | C19: 0000320193 | D19: 2023 | E19: 2023-09-30 | F19: 0000320193-23-000106 | G19: iTunes K.K. | H19: Apple Inc. | I19: subsidiary of registrant (direct/indirect not stated) | J19: 0 | K19: Japan | L19: Japan | O19: AAPL-S0018 | P19: 18 | S19: https://www.sec.gov/Archives/edgar/data/320193/000032019323000106/a10-kexhibit21109302023.htm
A20: AAPL | B20: Apple Inc. | C20: 0000320193 | D20: 2024 | E20: 2024-09-28 | F20: 0000320193-24-000123 | G20: Apple Asia Limited | H20: Apple Inc. | I20: subsidiary of registrant (direct/indirect not stated) | J20: 0 | K20: Hong Kong | L20: Hong Kong | O20: AAPL-S0001 | P20: 1 | S20: https://www.sec.gov/Archives/edgar/data/320193/000032019324000123/a10-kexhibit21109282024.htm
A21: AAPL | B21: Apple Inc. | C21: 0000320193 | D21: 2024 | E21: 2024-09-28 | F21: 0000320193-24-000123 | G21: Apple Asia LLC | H21: Apple Inc. | I21: subsidiary of registrant (direct/indirect not stated) | J21: 0 | K21: Delaware, U.S. | L21: United States | M21: Delaware | O21: AAPL-S0002 | P21: 2 | S21: https://www.sec.gov/Archives/edgar/data/320193/000032019324000123/a10-kexhibit21109282024.htm
A22: AAPL | B22: Apple Inc. | C22: 0000320193 | D22: 2024 | E22: 2024-09-28 | F22: 0000320193-24-000123 | G22: Apple Canada Inc. | H22: Apple Inc. | I22: subsidiary of registrant (direct/indirect not stated) | J22: 0 | K22: Canada | L22: Canada | O22: AAPL-S0003 | P22: 3 | S22: https://www.sec.gov/Archives/edgar/data/320193/000032019324000123/a10-kexhibit21109282024.htm
A23: AAPL | B23: Apple Inc. | C23: 0000320193 | D23: 2024 | E23: 2024-09-28 | F23: 0000320193-24-000123 | G23: Apple Computer Trading (Shanghai) Co., Ltd. | H23: Apple Inc. | I23: subsidiary of registrant (direct/indirect not stated) | J23: 0 | K23: China | L23: China | O23: AAPL-S0004 | P23: 4 | S23: https://www.sec.gov/Archives/edgar/data/320193/000032019324000123/a10-kexhibit21109282024.htm
A24: AAPL | B24: Apple Inc. | C24: 0000320193 | D24: 2024 | E24: 2024-09-28 | F24: 0000320193-24-000123 | G24: Apple Distribution International Limited | H24: Apple Inc. | I24: subsidiary of registrant (direct/indirect not stated) | J24: 0 | K24: Ireland | L24: Ireland | O24: AAPL-S0005 | P24: 5 | S24: https://www.sec.gov/Archives/edgar/data/320193/000032019324000123/a10-kexhibit21109282024.htm
A25: AAPL | B25: Apple Inc. | C25: 0000320193 | D25: 2024 | E25: 2024-09-28 | F25: 0000320193-24-000123 | G25: Apple India Private Limited | H25: Apple Inc. | I25: subsidiary of registrant (direct/indirect not stated) | J25: 0 | K25: India | L25: India | O25: AAPL-S0006 | P25: 6 | S25: https://www.sec.gov/Archives/edgar/data/320193/000032019324000123/a10-kexhibit21109282024.htm
A26: AAPL | B26: Apple Inc. | C26: 0000320193 | D26: 2024 | E26: 2024-09-28 | F26: 0000320193-24-000123 | G26: Apple Insurance Company, Inc. | H26: Apple Inc. | I26: subsidiary of registrant (direct/indirect not stated) | J26: 0 | K26: Arizona, U.S. | L26: United States | M26: Arizona | O26: AAPL-S0007 | P26: 7 | S26: https://www.sec.gov/Archives/edgar/data/320193/000032019324000123/a10-kexhibit21109282024.htm
A27: AAPL | B27: Apple Inc. | C27: 0000320193 | D27: 2024 | E27: 2024-09-28 | F27: 0000320193-24-000123 | G27: Apple Japan, Inc. | H27: Apple Inc. | I27: subsidiary of registrant (direct/indirect not stated) | J27: 0 | K27: Japan | L27: Japan | O27: AAPL-S0008 | P27: 8 | S27: https://www.sec.gov/Archives/edgar/data/320193/000032019324000123/a10-kexhibit21109282024.htm
A28: AAPL | B28: Apple Inc. | C28: 0000320193 | D28: 2024 | E28: 2024-09-28 | F28: 0000320193-24-000123 | G28: Apple Korea Limited | H28: Apple Inc. | I28: subsidiary of registrant (direct/indirect not stated) | J28: 0 | K28: South Korea | L28: South Korea | O28: AAPL-S0009 | P28: 9 | S28: https://www.sec.gov/Archives/edgar/data/320193/000032019324000123/a10-kexhibit21109282024.htm
A29: AAPL | B29: Apple Inc. | C29: 0000320193 | D29: 2024 | E29: 2024-09-28 | F29: 0000320193-24-000123 | G29: Apple Operations International Limited | H29: Apple Inc. | I29: subsidiary of registrant (direct/indirect not stated) | J29: 0 | K29: Ireland | L29: Ireland | O29: AAPL-S0010 | P29: 10 | S29: https://www.sec.gov/Archives/edgar/data/320193/000032019324000123/a10-kexhibit21109282024.htm
A30: AAPL | B30: Apple Inc. | C30: 0000320193 | D30: 2024 | E30: 2024-09-28 | F30: 0000320193-24-000123 | G30: Apple Operations Limited | H30: Apple Inc. | I30: subsidiary of registrant (direct/indirect not stated) | J30: 0 | K30: Ireland | L30: Ireland | O30: AAPL-S0011 | P30: 11 | S30: https://www.sec.gov/Archives/edgar/data/320193/000032019324000123/a10-kexhibit21109282024.htm
A31: AAPL | B31: Apple Inc. | C31: 0000320193 | D31: 2024 | E31: 2024-09-28 | F31: 0000320193-24-000123 | G31: Apple Operations Mexico, S.A. de C.V. | H31: Apple Inc. | I31: subsidiary of registrant (direct/indirect not stated) | J31: 0 | K31: Mexico | L31: Mexico | O31: AAPL-S0012 | P31: 12 | S31: https://www.sec.gov/Archives/edgar/data/320193/000032019324000123/a10-kexhibit21109282024.htm
A32: AAPL | B32: Apple Inc. | C32: 0000320193 | D32: 2024 | E32: 2024-09-28 | F32: 0000320193-24-000123 | G32: Apple Pty Limited | H32: Apple Inc. | I32: subsidiary of registrant (direct/indirect not stated) | J32: 0 | K32: Australia | L32: Australia | O32: AAPL-S0013 | P32: 13 | S32: https://www.sec.gov/Archives/edgar/data/320193/000032019324000123/a10-kexhibit21109282024.htm
A33: AAPL | B33: Apple Inc. | C33: 0000320193 | D33: 2024 | E33: 2024-09-28 | F33: 0000320193-24-000123 | G33: Apple Sales International Limited | H33: Apple Inc. | I33: subsidiary of registrant (direct/indirect not stated) | J33: 0 | K33: Ireland | L33: Ireland | O33: AAPL-S0014 | P33: 14 | S33: https://www.sec.gov/Archives/edgar/data/320193/000032019324000123/a10-kexhibit21109282024.htm
A34: AAPL | B34: Apple Inc. | C34: 0000320193 | D34: 2024 | E34: 2024-09-28 | F34: 0000320193-24-000123 | G34: Apple South Asia (Thailand) Limited | H34: Apple Inc. | I34: subsidiary of registrant (direct/indirect not stated) | J34: 0 | K34: Thailand | L34: Thailand | O34: AAPL-S0015 | P34: 15 | S34: https://www.sec.gov/Archives/edgar/data/320193/000032019324000123/a10-kexhibit21109282024.htm
A35: AAPL | B35: Apple Inc. | C35: 0000320193 | D35: 2024 | E35: 2024-09-28 | F35: 0000320193-24-000123 | G35: Apple Vietnam Limited Liability Company | H35: Apple Inc. | I35: subsidiary of registrant (direct/indirect not stated) | J35: 0 | K35: Vietnam | L35: Vietnam | O35: AAPL-S0016 | P35: 16 | S35: https://www.sec.gov/Archives/edgar/data/320193/000032019324000123/a10-kexhibit21109282024.htm
A36: AAPL | B36: Apple Inc. | C36: 0000320193 | D36: 2024 | E36: 2024-09-28 | F36: 0000320193-24-000123 | G36: Braeburn Capital, Inc. | H36: Apple Inc. | I36: subsidiary of registrant (direct/indirect not stated) | J36: 0 | K36: Nevada, U.S. | L36: United States | M36: Nevada | O36: AAPL-S0017 | P36: 17 | S36: https://www.sec.gov/Archives/edgar/data/320193/000032019324000123/a10-kexhibit21109282024.htm
A37: AAPL | B37: Apple Inc. | C37: 0000320193 | D37: 2024 | E37: 2024-09-28 | F37: 0000320193-24-000123 | G37: iTunes K.K. | H37: Apple Inc. | I37: subsidiary of registrant (direct/indirect not stated) | J37: 0 | K37: Japan | L37: Japan | O37: AAPL-S0018 | P37: 18 | S37: https://www.sec.gov/Archives/edgar/data/320193/000032019324000123/a10-kexhibit21109282024.htm
A38: AAPL | B38: Apple Inc. | C38: 0000320193 | D38: 2025 | E38: 2025-09-27 | F38: 0000320193-25-000079 | G38: Apple Asia Limited | H38: Apple Inc. | I38: subsidiary of registrant (direct/indirect not stated) | J38: 0 | K38: Hong Kong | L38: Hong Kong | O38: AAPL-S0001 | P38: 1 | S38: https://www.sec.gov/Archives/edgar/data/320193/000032019325000079/a10-kexhibit21109272025.htm
A39: AAPL | B39: Apple Inc. | C39: 0000320193 | D39: 2025 | E39: 2025-09-27 | F39: 0000320193-25-000079 | G39: Apple Asia LLC | H39: Apple Inc. | I39: subsidiary of registrant (direct/indirect not stated) | J39: 0 | K39: Delaware, U.S. | L39: United States | M39: Delaware | O39: AAPL-S0002 | P39: 2 | S39: https://www.sec.gov/Archives/edgar/data/320193/000032019325000079/a10-kexhibit21109272025.htm
A40: AAPL | B40: Apple Inc. | C40: 0000320193 | D40: 2025 | E40: 2025-09-27 | F40: 0000320193-25-000079 | G40: Apple Canada Inc. | H40: Apple Inc. | I40: subsidiary of registrant (direct/indirect not stated) | J40: 0 | K40: Canada | L40: Canada | O40: AAPL-S0003 | P40: 3 | S40: https://www.sec.gov/Archives/edgar/data/320193/000032019325000079/a10-kexhibit21109272025.htm
...

Sheet QA
A1: parent_ticker | B1: fiscal_year | C1: accession | D1: source_file | E1: rows_parsed | F1: duplicate_names | G1: missing_jurisdiction | H1: multi_level | I1: parse_method | J1: status
A2: AAPL | B2: 2025 | C2: 0000320193-25-000079 | D2: raw/AAPL_FY2025_0000320193-25-000079_ex21.md | E2: 19 | F2: 0 | G2: 0 | H2: 0 | I2: text_lines:pipe | J2: OK
A3: AAPL | B3: 2024 | C3: 0000320193-24-000123 | D3: raw/AAPL_FY2024_0000320193-24-000123_ex21.md | E3: 18 | F3: 0 | G3: 0 | H3: 0 | I3: text_lines:pipe | J3: OK
A4: AAPL | B4: 2023 | C4: 0000320193-23-000106 | D4: raw/AAPL_FY2023_0000320193-23-000106_ex21.md | E4: 18 | F4: 0 | G4: 0 | H4: 0 | I4: text_lines:pipe | J4: OK
A5: MSFT | B5: 2026 | C5: 0001193125-26-323660 | D5: raw/MSFT_FY2026_0001193125-26-323660_ex21.md | E5: 8 | F5: 0 | G5: 0 | H5: 0 | I5: text_lines:pipe | J5: OK
A6: MSFT | B6: 2025 | C6: 0000950170-25-100235 | D6: raw/MSFT_FY2025_0000950170-25-100235_ex21.md | E6: 8 | F6: 0 | G6: 0 | H6: 0 | I6: text_lines:pipe | J6: OK
A7: MSFT | B7: 2024 | C7: 0000950170-24-087843 | D7: raw/MSFT_FY2024_0000950170-24-087843_ex21.md | E7: 9 | F7: 0 | G7: 0 | H7: 0 | I7: text_lines:pipe | J7: OK
